Workbook

Sheet Cover
B2: ADVANCED MICRO DEVICES, INC. (AMD)
B3: Discounted Cash Flow (DCF) Valuation Model
B5: Overview
B6: This workbook presents a complete DCF valuation of AMD using historical financial data from fiscal years 2021-2025 and projected free cash flows for 2026-2030. All projections are driven by formulas linked to the Assumptions sheet — change any input (yellow cells) to see the valuation update instantly.
B9: Data Sources | D9: Key Valuation Outputs (Live) | G9: Instructions
B10: • 2021 10-K (FY ended Dec 25, 2021) — Historical financials | D10: Implied Share Price: | E10: ='DCF Valuation'!C36 -> 71.949723 | G10: 1. Yellow cells = inputs (change these to update the model).
B11: • 2022 10-K (FY ended Dec 31, 2022) — Historical financials | D11: Enterprise Value ($M): | E11: ='DCF Valuation'!C30 -> 110407.75 | G11: 2. Green cells = calculated via formulas (do not overwrite).
B12: • 2023 10-K (FY ended Dec 30, 2023) — Historical financials | D12: Equity Value ($M): | E12: ='DCF Valuation'!C33 -> 117709.75 | G12: 3. Navigate using tabs at the bottom of the workbook.
B13: • 2024 10-K (FY ended Dec 28, 2024) — [provided by user] | D13: WACC: | E13: =WACC!C24 -> 0.13789625 | G13: 4. Assumptions sheet contains all key drivers.
B14: • 2025 10-K/A (FY ended Dec 27, 2025) — [provided by user] | D14: Terminal Growth Rate: | E14: =Assumptions!C45 -> 0.03 | G14: 5. Sensitivity sheet shows per-share value across WACC × terminal growth.
B15: • Federal Reserve (FRED) — 10-year U.S. Treasury yield (risk-free rate) | D15: FY2025 Revenue ($M): | E15: =Historicals!G8 -> 34639 | G15: 6. All dollar amounts are in $ millions unless otherwise noted.
B16: • Damodaran Online — Equity risk premium benchmarks | D16: FY2025 Operating Income ($M): | E16: =Historicals!G24 -> 3694
B17: • AMD investor presentations — AI strategy, OpenAI partnership | D17: Diluted Shares (M): | E17: =Assumptions!C41 -> 1636
B38: Reference: AMD closing price on Jan 30, 2026: $236.73
B39: Note: OpenAI warrant (up to 160M shares at $0.01) not included in base case.

Sheet Historicals
B2: AMD Historical Financials (2021-2025)
B4: ($ in millions, except per-share) | C4: 2021 | D4: 2022 | E4: 2023 | F4: 2024 | G4: 2025
B5: Source: | C5: 2021 10-K | D5: 2022 10-K | E5: 2023 10-K | F5: 2024 10-K | G5: 2025 10-K/A
B7: INCOME STATEMENT
B8: Net Revenue | C8: 16434 | D8: 23601 | E8: 22680 | F8: 25785 | G8: 34639
B9: YoY Growth | C9: n/a | D9: =D8/C8-1 -> 0.43610807 | E9: =E8/D8-1 -> -0.03902377 | F9: =F8/E8-1 -> 0.13690476 | G9: =G8/F8-1 -> 0.34337793
B10: Cost of Sales (excl. amort.) | C10: 7609 | D10: 11550 | E10: 11278 | F10: 12114 | G10: 16456
B11: Amort. of Acq. Intangibles (COGS) | C11: 509 | D11: 1448 | E11: 942 | F11: 946 | G11: 1031
B12: Gross Profit | C12: =C8-C10-C11 -> 8316 | D12: =D8-D10-D11 -> 10603 | E12: =E8-E10-E11 -> 10460 | F12: =F8-F10-F11 -> 12725 | G12: =G8-G10-G11 -> 17152
B13: Gross Margin | C13: =C12/C8 -> 0.5060241 | D13: =D12/D8 -> 0.44926062 | E13: =E12/E8 -> 0.46119929 | F13: =F12/F8 -> 0.49350398 | G13: =G12/G8 -> 0.49516441
B15: OPERATING EXPENSES
B16: Research & Development | C16: 4407 | D16: 5005 | E16: 5872 | F16: 6456 | G16: 8091
B17: R&D % of Revenue | C17: =C16/C8 -> 0.26816356 | D17: =D16/D8 -> 0.21206729 | E17: =E16/E8 -> 0.25890653 | F17: =F16/F8 -> 0.25037813 | G17: =G16/G8 -> 0.23358065
B18: Marketing, Gen. & Admin. | C18: 1905 | D18: 2336 | E18: 2352 | F18: 2783 | G18: 4144
B19: MG&A % of Revenue | C19: =C18/C8 -> 0.11591822 | D19: =D18/D8 -> 0.098978857 | E19: =E18/E8 -> 0.1037037 | F19: =F18/F8 -> 0.10793097 | G19: =G18/G8 -> 0.11963394
B20: Amort. of Acq. Intangibles (OpEx) | C20: 525 | D20: 2100 | E20: 1869 | F20: 1448 | G20: 1223
B21: Restructuring Charges | C21: 0 | D21: 0 | E21: 0 | F21: 186 | G21: 0
B22: Licensing Gain (reduces OpEx) | C22: 47 | D22: 102 | E22: 34 | F22: 48 | G22: 0
B23: Total Operating Expenses | C23: =C16+C18+C20+C21-C22 -> 6790 | D23: =D16+D18+D20+D21-D22 -> 9339 | E23: =E16+E18+E20+E21-E22 -> 10059 | F23: =F16+F18+F20+F21-F22 -> 10825 | G23: =G16+G18+G20+G21-G22 -> 13458
B24: Operating Income | C24: =C12-C23 -> 1526 | D24: =D12-D23 -> 1264 | E24: =E12-E23 -> 401 | F24: =F12-F23 -> 1900 | G24: =G12-G23 -> 3694
B25: Operating Margin | C25: =C24/C8 -> 0.092856274 | D25: =D24/D8 -> 0.053557053 | E25: =E24/E8 -> 0.017680776 | F25: =F24/F8 -> 0.073686252 | G25: =G24/G8 -> 0.1066428
B26: Interest Expense | C26: 250 | D26: 88 | E26: 106 | F26: 92 | G26: 131
B27: Other Income (Expense), Net | C27: 25 | D27: 8 | E27: 197 | F27: 181 | G27: 577
B28: Pre-Tax Income | C28: =C24-C26+C27 -> 1301 | D28: =D24-D26+D27 -> 1184 | E28: =E24-E26+E27 -> 492 | F28: =F24-F26+F27 -> 1989 | G28: =G24-G26+G27 -> 4140
B29: Income Tax (Provision) Benefit | C29: 525 | D29: 122 | E29: -346 | F29: 381 | G29: -103
B30: Effective Tax Rate | C30: =C29/C28 -> 0.40353574 | D30: =D29/D28 -> 0.10304054 | E30: =E29/E28 -> -0.70325203 | F30: =F29/F28 -> 0.19155354 | G30: =G29/G28 -> -0.024879227
B31: Net Income | C31: 3162 | D31: 1320 | E31: 854 | F31: 1641 | G31: 4335
B32: Net Margin | C32: =C31/C8 -> 0.19240599 | D32: =D31/D8 -> 0.055929833 | E32: =E31/E8 -> 0.037654321 | F32: =F31/F8 -> 0.063641652 | G32: =G31/G8 -> 0.12514795
B33: Diluted EPS ($) | C33: 2.58 | D33: 0.84 | E33: 0.53 | F33: 1 | G33: 2.65
B34: Diluted Shares (M) | C34: 1225 | D34: 1571 | E34: 1625 | F34: 1637 | G34: 1636
B36: CASH FLOW & CAPEX
B37: Operating Cash Flow (Cont. Ops) | C37: 2730 | D37: 3565 | E37: 1667 | F37: 3041 | G37: 6493
B38: Capital Expenditures | C38: 286 | D38: 450 | E38: 546 | F38: 636 | G38: 974
B39: Free Cash Flow (FCF) | C39: =C37-C38 -> 2444 | D39: =D37-D38 -> 3115 | E39: =E37-E38 -> 1121 | F39: =F37-F38 -> 2405 | G39: =G37-G38 -> 5519
B40: FCF Margin | C40: =C39/C8 -> 0.14871608 | D40: =D39/D8 -> 0.13198593 | E40: =E39/E8 -> 0.049426808 | F40: =F39/F8 -> 0.093271282 | G40: =G39/G8 -> 0.15932908
B41: CapEx % of Revenue | C41: =C38/C8 -> 0.017402945 | D41: =D38/D8 -> 0.019066989 | E41: =E38/E8 -> 0.024074074 | F41: =F38/F8 -> 0.024665503 | G41: =G38/G8 -> 0.028118595
B42: Depreciation & Amort. (excl. acq.) | C42: 580 | D42: 626 | E42: 642 | F42: 671 | G42: 750
B43: Stock-Based Compensation | C43: 1256 | D43: 1081 | E43: 1384 | F43: 1407 | G43: 1638
B44: SBC % of Revenue | C44: =C43/C8 -> 0.07642692 | D44: =D43/D8 -> 0.045803144 | E44: =E43/E8 -> 0.061022928 | F44: =F43/F8 -> 0.054566608 | G44: =G43/G8 -> 0.047287739
B46: BALANCE SHEET (Year-End)
...

Sheet Assumptions
B2: DCF Model Assumptions
B4: All yellow cells are inputs. Change to update the entire model.
B5: Projection Year → | D5: 2026 | E5: 2027 | F5: 2028 | G5: 2029 | H5: 2030
B7: REVENUE GROWTH
B8: Revenue Growth Rate (%) | D8: 0.32 | E8: 0.24 | F8: 0.18 | G8: 0.14 | H8: 0.11
B9: Rationale: OpenAI 6GW partnership + MI350X/MI450 ramp;
B10: decelerating as AI infrastructure spend normalizes.
B12: PROFITABILITY MARGINS
B13: Gross Margin (%) | D13: 0.51 | E13: 0.52 | F13: 0.525 | G13: 0.53 | H13: 0.53
B14: Rationale: Data Center mix shift (higher margin) offsets competition.
B15: R&D % of Revenue (%) | D15: 0.22 | E15: 0.2 | F15: 0.19 | G15: 0.18 | H15: 0.17
B16: Rationale: Operating leverage as revenue scales faster than AI R&D.
B17: MG&A % of Revenue (%) | D17: 0.11 | E17: 0.1 | F17: 0.095 | G17: 0.09 | H17: 0.085
B18: Rationale: Go-to-market costs scale sub-linearly with revenue.
B19: Amort. of Acq. Intangibles ($M, fixed) | D19: 2153 | E19: 2036 | F19: 1923 | G19: 1691 | H19: 1454
B20: Source: AMD 2025 10-K, Note 6 — Acquisition-related Intangible Assets.
B22: TAX, CAPEX & WORKING CAPITAL
B23: Effective Tax Rate (%) | D23: 0.15 | E23: 0.15 | F23: 0.15 | G23: 0.15 | H23: 0.15
B24: Rationale: Normalized from 2025 (-2.5%, one-time IRS release) & 2024 (19%).
B25: CapEx % of Revenue (%) | D25: 0.03 | E25: 0.03 | F25: 0.028 | G25: 0.025 | H25: 0.025
B26: Rationale: Data center capacity buildout; 2025 was 2.8%.
B27: D&A % of Revenue (excl. acq. amort.) (%) | D27: 0.025 | E27: 0.025 | F27: 0.025 | G27: 0.025 | H27: 0.025
B28: SBC % of Revenue (%) | D28: 0.05 | E28: 0.048 | F28: 0.045 | G28: 0.043 | H28: 0.04
B29: Rationale: AI talent competition; declining as revenue scales.
B30: ΔNWC % of ΔRevenue (%) | D30: 0.15 | E30: 0.12 | F30: 0.1 | G30: 0.08 | H30: 0.08
B31: Rationale: Inventory builds for product ramps; normalizing over time.
B33: WACC COMPONENTS
B34: Risk-Free Rate (10Y UST, %) | C34: 0.0425 | D34: FRED data, early 2026
B35: Equity Risk Premium (%) | C35: 0.055 | D35: Damodaran 2025 estimate
B36: Beta (5Y monthly) | C36: 1.75 | D36: AMD volatility vs. S&P 500
B37: Pre-Tax Cost of Debt (%) | C37: 0.043 | D37: Weighted avg of AMD notes
B38: Market Cap ($M) | C38: 385800 | D38: 1,630M shares × $236.73
B39: Total Debt ($M, principal) | C39: 3250 | D39: 2025 10-K, Note 9
B40: Total Cash + ST Investments ($M) | C40: 10552 | D40: 2025 10-K Balance Sheet
B41: Diluted Shares (M) | C41: 1636 | D41: 2025 10-K, Note 13
B44: TERMINAL VALUE
B45: Terminal Growth Rate (%) | C45: 0.03
B46: Rationale: Long-term GDP growth + inflation.

Sheet WACC
B2: Weighted Average Cost of Capital (WACC)
B4: Component | C4: Value | D4: Formula / Source
B6: COST OF EQUITY (CAPM)
B7: Risk-Free Rate (Rf) | C7: =Assumptions!C34 -> 0.0425 | D7: 10-year U.S. Treasury yield
B8: Equity Risk Premium (ERP) | C8: =Assumptions!C35 -> 0.055 | D8: Damodaran 2025 estimate
B9: Beta (β) | C9: =Assumptions!C36 -> 1.75 | D9: 5-year monthly regression vs. S&P 500
B10: Cost of Equity = Rf + β × ERP | C10: =C7+C9*C8 -> 0.13875 | D10: CAPM formula
B12: COST OF DEBT
B13: Pre-Tax Cost of Debt | C13: =Assumptions!C37 -> 0.043 | D13: Weighted avg: 4.212%('26), 4.319%('28), 2.375%('30), 3.924%('32), 4.393%('52)
B14: Tax Rate | C14: =Assumptions!D23 -> 0.15 | D14: Normalized effective tax rate
B15: After-Tax Cost of Debt = Kd × (1 - t) | C15: =C13*(1-C14) -> 0.03655
B17: CAPITAL STRUCTURE
B18: Market Value of Equity ($M) | C18: =Assumptions!C38 -> 385800 | D18: Shares × current price
B19: Market Value of Debt ($M) | C19: =Assumptions!C39 -> 3250 | D19: Book value ≈ market value (fixed-rate notes)
B20: Total Capital ($M) | C20: =C18+C19 -> 389050
B21: Weight of Equity (We) | C21: =C18/C20 -> 0.99164632
B22: Weight of Debt (Wd) | C22: =C19/C20 -> 0.008353682
B24: WACC = We × Ke + Wd × Kd×(1-t) | C24: =C21*C10+C22*C15 -> 0.13789625 | D24: Weighted average cost of capital

Sheet Projections
B2: Projected Financials & Free Cash Flow (2026-2030)
B4: ($ in millions) | C4: 2026 | D4: 2027 | E4: 2028 | F4: 2029 | G4: 2030
B6: PROJECTED INCOME STATEMENT
B7: Net Revenue | C7: =Historicals!G8*(1+Assumptions!D8) -> 45723.48 | D7: =C7*(1+Assumptions!E8) -> 56697.115 | E7: =D7*(1+Assumptions!F8) -> 66902.596 | F7: =E7*(1+Assumptions!G8) -> 76268.959 | G7: =F7*(1+Assumptions!H8) -> 84658.545
B8: YoY Growth | C8: =C7/Historicals!G8-1 -> 0.32 | D8: =D7/C7-1 -> 0.24 | E8: =E7/D7-1 -> 0.18 | F8: =F7/E7-1 -> 0.14 | G8: =G7/F7-1 -> 0.11
B9: Gross Profit | C9: =C7*Assumptions!D13 -> 23318.975 | D9: =D7*Assumptions!E13 -> 29482.5 | E9: =E7*Assumptions!F13 -> 35123.863 | F9: =F7*Assumptions!G13 -> 40422.548 | G9: =G7*Assumptions!H13 -> 44869.029
B10: Gross Margin | C10: =C9/C7 -> 0.51 | D10: =D9/D7 -> 0.52 | E10: =E9/E7 -> 0.525 | F10: =F9/F7 -> 0.53 | G10: =G9/G7 -> 0.53
B11: Research & Development | C11: =C7*Assumptions!D15 -> 10059.166 | D11: =D7*Assumptions!E15 -> 11339.423 | E11: =E7*Assumptions!F15 -> 12711.493 | F11: =F7*Assumptions!G15 -> 13728.413 | G11: =G7*Assumptions!H15 -> 14391.953
B12: Marketing, Gen. & Admin. | C12: =C7*Assumptions!D17 -> 5029.5828 | D12: =D7*Assumptions!E17 -> 5669.7115 | E12: =E7*Assumptions!F17 -> 6355.7466 | F12: =F7*Assumptions!G17 -> 6864.2063 | G12: =G7*Assumptions!H17 -> 7195.9763
B13: Amort. of Acq. Intangibles | C13: =Assumptions!D19 -> 2153 | D13: =Assumptions!E19 -> 2036 | E13: =Assumptions!F19 -> 1923 | F13: =Assumptions!G19 -> 1691 | G13: =Assumptions!H19 -> 1454
B14: EBIT (Operating Income) | C14: =C9-C11-C12-C13 -> 6077.2264 | D14: =D9-D11-D12-D13 -> 10437.365 | E14: =E9-E11-E12-E13 -> 14133.623 | F14: =F9-F11-F12-F13 -> 18138.929 | G14: =G9-G11-G12-G13 -> 21827.1
B15: EBIT Margin | C15: =C14/C7 -> 0.1329126 | D15: =D14/D7 -> 0.18408988 | E15: =E14/E7 -> 0.21125672 | F15: =F14/F7 -> 0.23782846 | G15: =G14/G7 -> 0.25782512
B16: Taxes on EBIT | C16: =C14*Assumptions!D23 -> 911.58396 | D16: =D14*Assumptions!E23 -> 1565.6048 | E16: =E14*Assumptions!F23 -> 2120.0435 | F16: =F14*Assumptions!G23 -> 2720.8394 | G16: =G14*Assumptions!H23 -> 3274.065
B17: NOPAT | C17: =C14-C16 -> 5165.6424 | D17: =D14-D16 -> 8871.7605 | E17: =E14-E16 -> 12013.58 | F17: =F14-F16 -> 15418.09 | G17: =G14-G16 -> 18553.035
B19: FREE CASH FLOW CALCULATION
B20: (+) Amortization of Acq. Intangibles | C20: =C13 -> 2153 | D20: =D13 -> 2036 | E20: =E13 -> 1923 | F20: =F13 -> 1691 | G20: =G13 -> 1454
B21: (+) Depreciation & Amort. (other) | C21: =C7*Assumptions!D27 -> 1143.087 | D21: =D7*Assumptions!E27 -> 1417.4279 | E21: =E7*Assumptions!F27 -> 1672.5649 | F21: =F7*Assumptions!G27 -> 1906.724 | G21: =G7*Assumptions!H27 -> 2116.4636
B22: (–) Stock-Based Compensation | C22: =C7*Assumptions!D28 -> 2286.174 | D22: =D7*Assumptions!E28 -> 2721.4615 | E22: =E7*Assumptions!F28 -> 3010.6168 | F22: =F7*Assumptions!G28 -> 3279.5653 | G22: =G7*Assumptions!H28 -> 3386.3418
B23: (–) Capital Expenditures | C23: =C7*Assumptions!D25 -> 1371.7044 | D23: =D7*Assumptions!E25 -> 1700.9135 | E23: =E7*Assumptions!F25 -> 1873.2727 | F23: =F7*Assumptions!G25 -> 1906.724 | G23: =G7*Assumptions!H25 -> 2116.4636
B24: (–) Change in Net Working Capital | C24: =(C7-Historicals!G8)*Assumptions!D30 -> 1662.672 | D24: =(D7-C7)*Assumptions!E30 -> 1316.8362 | E24: =(E7-D7)*Assumptions!F30 -> 1020.5481 | F24: =(F7-E7)*Assumptions!G30 -> 749.30907 | G24: =(G7-F7)*Assumptions!H30 -> 671.16684
B25: Unlevered Free Cash Flow | C25: =C17+C20+C21-C22-C23-C24 -> 3141.179 | D25: =D17+D20+D21-D22-D23-D24 -> 6585.9772 | E25: =E17+E20+E21-E22-E23-E24 -> 9704.7069 | F25: =F17+F20+F21-F22-F23-F24 -> 13080.216 | G25: =G17+G20+G21-G22-G23-G24 -> 15949.526
B26: FCF Margin | C26: =C25/C7 -> 0.068699474 | D26: =D25/D7 -> 0.11616071 | E26: =E25/E7 -> 0.14505725 | F26: =F25/F7 -> 0.17150117 | G26: =G25/G7 -> 0.1883983
B27: Cumulative FCF | C27: =C25 -> 3141.179 | D27: =C27+D25 -> 9727.1563 | E27: =D27+E25 -> 19431.863 | F27: =E27+F25 -> 32512.079 | G27: =F27+G25 -> 48461.605

Sheet DCF Valuation
B2: DCF Valuation Summary
B4: Year | C4: Free Cash Flow ($M) | D4: Discount Factor | E4: Present Value ($M)
B5: WACC: | C5: =WACC!C24 -> 0.13789625 | D5: (linked from WACC sheet)
B7: FY2026 | C7: =Projections!C25 -> 3141.179 | D7: =1/(1+$C$5)^1 -> 0.87881474 | E7: =C7*D7 -> 2760.5144
B8: FY2027 | C8: =Projections!D25 -> 6585.9772 | D8: =1/(1+$C$5)^2 -> 0.77231535 | E8: =C8*D8 -> 5086.4513
B9: FY2028 | C9: =Projections!E25 -> 9704.7069 | D9: =1/(1+$C$5)^3 -> 0.67872211 | E9: =C9*D9 -> 6586.7991
B10: FY2029 | C10: =Projections!F25 -> 13080.216 | D10: =1/(1+$C$5)^4 -> 0.59647099 | E10: =C10*D10 -> 7801.9693
B11: FY2030 | C11: =Projections!G25 -> 15949.526 | D11: =1/(1+$C$5)^5 -> 0.5241875 | E11: =C11*D11 -> 8360.5423
B13: Sum of PV of FCF (2026-2030) | E13: =SUM(E7:E11) -> 30596.276
B15: TERMINAL VALUE
B16: FCF in 2030 (final year) | C16: =C11 -> 15949.526
B17: Terminal Growth Rate (g) | C17: =Assumptions!C45 -> 0.03
B18: Terminal Value = FCF×(1+g)/(WACC-g) | C18: =C16*(1+C17)/(C5-C17) -> 152257.48 | E18: Gordon Growth Model
B19: Discount Factor (Year 5) | C19: =D11 -> 0.5241875
B20: PV of Terminal Value | C20: =C18*C19 -> 79811.47
B22: ENTERPRISE VALUE & EQUITY VALUE
B23: PV of FCF (2026-2030) | C23: =E13 -> 30596.276
B24: PV of Terminal Value | C24: =C20 -> 79811.47
B25: (+) Cumulative FCF adjustment | C25: 0 | E25: No mid-year convention adjustment
B26: Enterprise Value | C26: =C23+C24+C25 -> 110407.75
B28: (–) Total Debt | C28: =Assumptions!C39 -> 3250 | E28: From 2025 10-K Balance Sheet
B29: (+) Cash & ST Investments | C29: =Assumptions!C40 -> 10552 | E29: From 2025 10-K Balance Sheet
B30: Enterprise Value (ref) | C30: =C26 -> 110407.75
B31: Net Debt | C31: =C28-C29 -> -7302
B33: Equity Value | C33: =C26-C28+C29 -> 117709.75
B35: Diluted Shares Outstanding (M) | C35: =Assumptions!C41 -> 1636 | E35: From 2025 10-K Note 13
B36: Implied Share Price | C36: =C33/C35 -> 71.949723
B38: Reference: AMD price on Jan 30, 2026 | C38: 236.73
B39: Implied Premium/(Discount) vs. Market | C39: =C36/C38-1 -> -0.69606842
B41: Notes:
B42: • OpenAI warrant (up to 160M shares at $0.01) excluded from base case; potential dilution.
B43: • SBC treated as cash expense (subtracted from FCF) per conservative methodology.
B44: • Amortization of acquisition-related intangibles added back (non-cash).
B45: • Tax rate normalized to 15% (2025 was -2.5% due to one-time IRS release).
B46: • Terminal value uses Gordon Growth Model with 3.0% perpetual growth.

Sheet Sensitivity
B2: Sensitivity Analysis: Implied Share Price
B4: This table shows the implied share price at various WACC and terminal growth rate combinations.
B5: All other assumptions remain unchanged from the base case.
B7: WACC ↓ \ Term. Growth → | C7: 0.02 | D7: 0.025 | E7: 0.03 | F7: 0.035 | G7: 0.04
B8: 0.11 | C8: =(((Projections!C25/(1+$B8)^1+Projections!D25/(1+$B8)^2+Projections!E25/(1+$B8)^3+Projections!F25/(1+$B8)^4+Projections!G25/(1+$B8)^5)+((Projections!G25*(1+C$7)/($B8-C$7))/(1+$B8)^5))-Assumptions!C39+Assumptions!C40)/Assumptions!C41 -> 90.420451 | D8: =(((Projections!C25/(1+$B8)^1+Projections!D25/(1+$B8)^2+Projections!E25/(1+$B8)^3+Projections!F25/(1+$B8)^4+Projections!G25/(1+$B8)^5)+((Projections!G25*(1+D$7)/($B8-D$7))/(1+$B8)^5))-Assumptions!C39+Assumptions!C40)/Assumptions!C41 -> 94.617859 | E8: =(((Projections!C25/(1+$B8)^1+Projections!D25/(1+$B8)^2+Projections!E25/(1+$B8)^3+Projections!F25/(1+$B8)^4+Projections!G25/(1+$B8)^5)+((Projections!G25*(1+E$7)/($B8-E$7))/(1+$B8)^5))-Assumptions!C39+Assumptions!C40)/Assumptions!C41 -> 99.339943 | F8: =(((Projections!C25/(1+$B8)^1+Projections!D25/(1+$B8)^2+Projections!E25/(1+$B8)^3+Projections!F25/(1+$B8)^4+Projections!G25/(1+$B8)^5)+((Projections!G25*(1+F$7)/($B8-F$7))/(1+$B8)^5))-Assumptions!C39+Assumptions!C40)/Assumptions!C41 -> 104.69164 | G8: =(((Projections!C25/(1+$B8)^1+Projections!D25/(1+$B8)^2+Projections!E25/(1+$B8)^3+Projections!F25/(1+$B8)^4+Projections!G25/(1+$B8)^5)+((Projections!G25*(1+G$7)/($B8-G$7))/(1+$B8)^5))-Assumptions!C39+Assumptions!C40)/Assumptions!C41 -> 110.80786
B9: 0.12 | C9: =(((Projections!C25/(1+$B9)^1+Projections!D25/(1+$B9)^2+Projections!E25/(1+$B9)^3+Projections!F25/(1+$B9)^4+Projections!G25/(1+$B9)^5)+((Projections!G25*(1+C$7)/($B9-C$7))/(1+$B9)^5))-Assumptions!C39+Assumptions!C40)/Assumptions!C41 -> 80.647543 | D9: =(((Projections!C25/(1+$B9)^1+Projections!D25/(1+$B9)^2+Projections!E25/(1+$B9)^3+Projections!F25/(1+$B9)^4+Projections!G25/(1+$B9)^5)+((Projections!G25*(1+D$7)/($B9-D$7))/(1+$B9)^5))-Assumptions!C39+Assumptions!C40)/Assumptions!C41 -> 83.908452 | E9: =(((Projections!C25/(1+$B9)^1+Projections!D25/(1+$B9)^2+Projections!E25/(1+$B9)^3+Projections!F25/(1+$B9)^4+Projections!G25/(1+$B9)^5)+((Projections!G25*(1+E$7)/($B9-E$7))/(1+$B9)^5))-Assumptions!C39+Assumptions!C40)/Assumptions!C41 -> 87.531686 | F9: =(((Projections!C25/(1+$B9)^1+Projections!D25/(1+$B9)^2+Projections!E25/(1+$B9)^3+Projections!F25/(1+$B9)^4+Projections!G25/(1+$B9)^5)+((Projections!G25*(1+F$7)/($B9-F$7))/(1+$B9)^5))-Assumptions!C39+Assumptions!C40)/Assumptions!C41 -> 91.581182 | G9: =(((Projections!C25/(1+$B9)^1+Projections!D25/(1+$B9)^2+Projections!E25/(1+$B9)^3+Projections!F25/(1+$B9)^4+Projections!G25/(1+$B9)^5)+((Projections!G25*(1+G$7)/($B9-G$7))/(1+$B9)^5))-Assumptions!C39+Assumptions!C40)/Assumptions!C41 -> 96.136865
B10: 0.13 | C10: =(((Projections!C25/(1+$B10)^1+Projections!D25/(1+$B10)^2+Projections!E25/(1+$B10)^3+Projections!F25/(1+$B10)^4+Projections!G25/(1+$B10)^5)+((Projections!G25*(1+C$7)/($B10-C$7))/(1+$B10)^5))-Assumptions!C39+Assumptions!C40)/Assumptions!C41 -> 72.687258 | D10: =(((Projections!C25/(1+$B10)^1+Projections!D25/(1+$B10)^2+Projections!E25/(1+$B10)^3+Projections!F25/(1+$B10)^4+Projections!G25/(1+$B10)^5)+((Projections!G25*(1+D$7)/($B10-D$7))/(1+$B10)^5))-Assumptions!C39+Assumptions!C40)/Assumptions!C41 -> 75.275702 | E10: =(((Projections!C25/(1+$B10)^1+Projections!D25/(1+$B10)^2+Projections!E25/(1+$B10)^3+Projections!F25/(1+$B10)^4+Projections!G25/(1+$B10)^5)+((Projections!G25*(1+E$7)/($B10-E$7))/(1+$B10)^5))-Assumptions!C39+Assumptions!C40)/Assumptions!C41 -> 78.12299 | F10: =(((Projections!C25/(1+$B10)^1+Projections!D25/(1+$B10)^2+Projections!E25/(1+$B10)^3+Projections!F25/(1+$B10)^4+Projections!G25/(1+$B10)^5)+((Projections!G25*(1+F$7)/($B10-F$7))/(1+$B10)^5))-Assumptions!C39+Assumptions!C40)/Assumptions!C41 -> 81.269993 | G10: =(((Projections!C25/(1+$B10)^1+Projections!D25/(1+$B10)^2+Projections!E25/(1+$B10)^3+Projections!F25/(1+$B10)^4+Projections!G25/(1+$B10)^5)+((Projections!G25*(1+G$7)/($B10-G$7))/(1+$B10)^5))-Assumptions!C39+Assumptions!C40)/Assumptions!C41 -> 84.766663
B11: 0.14 | C11: =(((Projections!C25/(1+$B11)^1+Projections!D25/(1+$B11)^2+Projections!E25/(1+$B11)^3+Projections!F25/(1+$B11)^4+Projections!G25/(1+$B11)^5)+((Projections!G25*(1+C$7)/($B11-C$7))/(1+$B11)^5))-Assumptions!C39+Assumptions!C40)/Assumptions!C41 -> 66.084996 | D11: =(((Projections!C25/(1+$B11)^1+Projections!D25/(1+$B11)^2+Projections!E25/(1+$B11)^3+Projections!F25/(1+$B11)^4+Projections!G25/(1+$B11)^5)+((Projections!G25*(1+D$7)/($B11-D$7))/(1+$B11)^5))-Assumptions!C39+Assumptions!C40)/Assumptions!C41 -> 68.176391 | E11: =(((Projections!C25/(1+$B11)^1+Projections!D25/(1+$B11)^2+Projections!E25/(1+$B11)^3+Projections!F25/(1+$B11)^4+Projections!G25/(1+$B11)^5)+((Projections!G25*(1+E$7)/($B11-E$7))/(1+$B11)^5))-Assumptions!C39+Assumptions!C40)/Assumptions!C41 -> 70.457912 | F11: =(((Projections!C25/(1+$B11)^1+Projections!D25/(1+$B11)^2+Projections!E25/(1+$B11)^3+Projections!F25/(1+$B11)^4+Projections!G25/(1+$B11)^5)+((Projections!G25*(1+F$7)/($B11-F$7))/(1+$B11)^5))-Assumptions!C39+Assumptions!C40)/Assumptions!C41 -> 72.956721 | G11: =(((Projections!C25/(1+$B11)^1+Projections!D25/(1+$B11)^2+Projections!E25/(1+$B11)^3+Projections!F25/(1+$B11)^4+Projections!G25/(1+$B11)^5)+((Projections!G25*(1+G$7)/($B11-G$7))/(1+$B11)^5))-Assumptions!C39+Assumptions!C40)/Assumptions!C41 -> 75.705412
B12: 0.15 | C12: =(((Projections!C25/(1+$B12)^1+Projections!D25/(1+$B12)^2+Projections!E25/(1+$B12)^3+Projections!F25/(1+$B12)^4+Projections!G25/(1+$B12)^5)+((Projections!G25*(1+C$7)/($B12-C$7))/(1+$B12)^5))-Assumptions!C39+Assumptions!C40)/Assumptions!C41 -> 60.526103 | D12: =(((Projections!C25/(1+$B12)^1+Projections!D25/(1+$B12)^2+Projections!E25/(1+$B12)^3+Projections!F25/(1+$B12)^4+Projections!G25/(1+$B12)^5)+((Projections!G25*(1+D$7)/($B12-D$7))/(1+$B12)^5))-Assumptions!C39+Assumptions!C40)/Assumptions!C41 -> 62.241204 | E12: =(((Projections!C25/(1+$B12)^1+Projections!D25/(1+$B12)^2+Projections!E25/(1+$B12)^3+Projections!F25/(1+$B12)^4+Projections!G25/(1+$B12)^5)+((Projections!G25*(1+E$7)/($B12-E$7))/(1+$B12)^5))-Assumptions!C39+Assumptions!C40)/Assumptions!C41 -> 64.099231 | F12: =(((Projections!C25/(1+$B12)^1+Projections!D25/(1+$B12)^2+Projections!E25/(1+$B12)^3+Projections!F25/(1+$B12)^4+Projections!G25/(1+$B12)^5)+((Projections!G25*(1+F$7)/($B12-F$7))/(1+$B12)^5))-Assumptions!C39+Assumptions!C40)/Assumptions!C41 -> 66.118825 | G12: =(((Projections!C25/(1+$B12)^1+Projections!D25/(1+$B12)^2+Projections!E25/(1+$B12)^3+Projections!F25/(1+$B12)^4+Projections!G25/(1+$B12)^5)+((Projections!G25*(1+G$7)/($B12-G$7))/(1+$B12)^5))-Assumptions!C39+Assumptions!C40)/Assumptions!C41 -> 68.322018
B13: 0.16 | C13: =(((Projections!C25/(1+$B13)^1+Projections!D25/(1+$B13)^2+Projections!E25/(1+$B13)^3+Projections!F25/(1+$B13)^4+Projections!G25/(1+$B13)^5)+((Projections!G25*(1+C$7)/($B13-C$7))/(1+$B13)^5))-Assumptions!C39+Assumptions!C40)/Assumptions!C41 -> 55.78589 | D13: =(((Projections!C25/(1+$B13)^1+Projections!D25/(1+$B13)^2+Projections!E25/(1+$B13)^3+Projections!F25/(1+$B13)^4+Projections!G25/(1+$B13)^5)+((Projections!G25*(1+D$7)/($B13-D$7))/(1+$B13)^5))-Assumptions!C39+Assumptions!C40)/Assumptions!C41 -> 57.210318 | E13: =(((Projections!C25/(1+$B13)^1+Projections!D25/(1+$B13)^2+Projections!E25/(1+$B13)^3+Projections!F25/(1+$B13)^4+Projections!G25/(1+$B13)^5)+((Projections!G25*(1+E$7)/($B13-E$7))/(1+$B13)^5))-Assumptions!C39+Assumptions!C40)/Assumptions!C41 -> 58.744319 | F13: =(((Projections!C25/(1+$B13)^1+Projections!D25/(1+$B13)^2+Projections!E25/(1+$B13)^3+Projections!F25/(1+$B13)^4+Projections!G25/(1+$B13)^5)+((Projections!G25*(1+F$7)/($B13-F$7))/(1+$B13)^5))-Assumptions!C39+Assumptions!C40)/Assumptions!C41 -> 60.401039 | G13: =(((Projections!C25/(1+$B13)^1+Projections!D25/(1+$B13)^2+Projections!E25/(1+$B13)^3+Projections!F25/(1+$B13)^4+Projections!G25/(1+$B13)^5)+((Projections!G25*(1+G$7)/($B13-G$7))/(1+$B13)^5))-Assumptions!C39+Assumptions!C40)/Assumptions!C41 -> 62.195819
B14: Base case WACC: | C14: =WACC!C24 -> 0.13789625 | D14: Base case TG: | E14: =Assumptions!C45 -> 0.03 | F14: Base case price: | G14: ='DCF Valuation'!C36 -> 71.949723
B16: Notes:
B17: • Each cell independently recalculates the entire DCF with the given WACC and TG.
B18: • All other assumptions (revenue growth, margins, CapEx, etc.) remain at base case.
B19: • Yellow input cells on the Assumptions sheet drive the base case.
